Workbook

Sheet Plan de tareas
A1: Plan de tareas — Proyecto CCMS Nav (Navantia)
A2: Perfiles: Full Stack Developer (decisiones importantes + backend/infra/tests) · UX/ILS Specialist (frontend) — misma persona, dos roles separados en el plan.
A4: ID | B4: Tarea | C4: Bloque | D4: Perfil | E4: Duración (días hábiles) | F4: Depende de | G4: ¿Paralelizable? | H4: Fecha inicio | I4: Fecha fin | J4: Notas / bloqueos
A5: A1 | B5: Solicitar a Navantia el protocolo de su IdP (SAML/ADFS u OIDC/Azure AD) | C5: A - Decisiones externas | D5: Full Stack Developer | E5: 1 | F5: — | G5: Sí | H5: 46272 | I5: =WORKDAY(H5,E5-1) -> 46272 | J5: Bloquea T-B8 (adaptador IdP Navantia) y la cobertura completa de tests/security/test_auth_federacion.py. No bloquea el resto del backend.
A6: A2 | B6: Solicitar a seguridad/compliance ATEXIS: tier aacf (T1-T4), guardrails G1-G12 exigibles, restricciones onshore/offshore, y si el aislamiento por proyecto (decisión A) es control suficiente por sí solo | C6: A - Decisiones externas | D6: Full Stack Developer | E6: 1 | F6: — | G6: Sí | H6: 46272 | I6: =WORKDAY(H6,E6-1) -> 46272 | J6: Riesgo abierto de alta prioridad (checklist Fase 6). No bloquea el build, pero debe cerrarse antes de dar el proyecto por conforme a compliance.
A7: A3 | B7: Cerrar con negocio/Navantia la lista definitiva de roles RBAC | C7: A - Decisiones externas | D7: Full Stack Developer | E7: 2 | F7: — | G7: Sí | H7: 46272 | I7: =WORKDAY(H7,E7-1) -> 46273 | J7: No bloquea el esquema (es catálogo, no constantes) ni T-B4 (que usa roles provisionales), pero sí condiciona qué datos semilla son realistas.
A8: A4 | B8: Confirmar alcance del worker de publicación: ¿RenderX + Compositor S80 desde el inicio, o solo Compositor S80? | C8: A - Decisiones externas | D8: Full Stack Developer | E8: 1 | F8: — | G8: Sí | H8: 46272 | I8: =WORKDAY(H8,E8-1) -> 46272 | J8: Bloquea T-D12 (worker/). RenderX ya está activo hoy como pieza transicional; sin esta confirmación no se puede acotar el alcance del primer build.
A9: A5 | B9: Decidir si se activa eXist-db en este build o se pospone | C9: A - Decisiones externas | D9: Full Stack Developer | E9: 1 | F9: — | G9: Sí | H9: 46272 | I9: =WORKDAY(H9,E9-1) -> 46272 | J9: Si la respuesta es 'sí', añade T-H1 (3 días) al plan. Si es 'no' (opción por defecto hoy), el proyecto sigue sin ese módulo, tal como está.
A10: B1 | B10: docker-compose.yml real + .env dev (PostgreSQL + OpenSearch) | C10: B - Infraestructura y core | D10: Full Stack Developer | E10: 1 | F10: — | G10: No | H10: 46272 | I10: =WORKDAY(H10,E10-1) -> 46272 | J10: Sustituye los marcadores TODO/.env.example ya creados por configuración funcional real, siguiendo el patrón de Fase 2 y Fase 5 del curso.
A11: B2 | B11: Aplicar el esquema de PostgreSQL (9 tablas base + proyecto + catálogo RBAC + tareas/comentarios/auditoría + 7 tablas del índice de extracción) | C11: B - Infraestructura y core | D11: Full Stack Developer | E11: 1 | F11: B1 | G11: No | H11: 46273 | I11: =WORKDAY(H11,E11-1) -> 46273 | J11: Migraciones desde fase-2-bases-de-datos/2-construccion_esquema_bd.md + extensiones propias de este proyecto.
A12: B3 | B12: core/config.py | C12: B - Infraestructura y core | D12: Full Stack Developer | E12: 0.5 | F12: B1 | G12: Sí | H12: 46274 | I12: =WORKDAY(H12,E12-1) -> 46273 | J12: HR0/HR8 de aacf: nada hardcodeado, todo configurable vía entorno.
A13: B4 | B13: Catálogo RBAC: tablas + datos semilla provisionales | C13: B - Infraestructura y core | D13: Full Stack Developer | E13: 1 | F13: B2 | G13: No | H13: 46275 | I13: =WORKDAY(H13,E13-1) -> 46275 | J13: Puede arrancar con roles provisionales sin esperar a T-A3 (decisión C: 'se cerrará más adelante'). Repoblar cuando T-A3 cierre.
A14: B5 | B14: core/seguridad.py — dependencia FastAPI de JWT + RBAC | C14: B - Infraestructura y core | D14: Full Stack Developer | E14: 2 | F14: B4 | G14: No | H14: 46276 | I14: =WORKDAY(H14,E14-1) -> 46279 | J14: Estructuralmente transversal: ningún router debe poder saltarse esta comprobación. Incluye el ejemplo de uso pendiente de verificar (marcado en estructura_carpetas.md).
A15: B6 | B15: core/proyecto_context.py — dependencia FastAPI de aislamiento multi-proyecto/cliente | C15: B - Infraestructura y core | D15: Full Stack Developer | E15: 1.5 | F15: B2 | G15: Sí | H15: 46280 | I15: =WORKDAY(H15,E15-1) -> 46280 | J15: La pieza más crítica del proyecto (decisión A). Debe quedar estructuralmente imposible de saltarse, no una convención a recordar.
A16: B7 | B16: auth/federacion.py + adaptador IdP ATEXIS/Keycloak | C16: B - Infraestructura y core | D16: Full Stack Developer | E16: 2 | F16: B5 | G16: No | H16: 46281 | I16: =WORKDAY(H16,E16-1) -> 46282 | J16: El lado ATEXIS puede construirse ya, sin depender de Navantia.
... A52: E13 | B52: Admin.tsx | C52: E - Frontend | D52: UX/ILS Specialist | E52: 2 | F52: E0, D10 | G52: Sí | H52: 46384 | I52: =WORKDAY(H52,E52-1) -> 46385 | J52: —
A55: Resumen de esfuerzo por perfil
A56: Perfil | B56: Días hábiles totales
A57: Full Stack Developer | B57: =SUMIFS(E5:E52,D5:D52,A57) -> 67
A58: UX/ILS Specialist | B58: =SUMIFS(E5:E52,D5:D52,A58) -> 24
A59: TOTAL | B59: =SUM(B57:B58) -> 91
A61: Nota: la tarea H1 (eXist-db) es condicional a la decisión A5 y no está incluida en la fecha fin del bloque de backend/CI (G1) ni en el total de esfuerzo — si A5 confirma activar eXist-db, sumar sus 3 días al camino crítico del backend antes de F1.

Sheet Gantt
A1: Gantt semanal — Proyecto CCMS Nav
A3: ID | B3: Tarea | C3: Perfil | D3: 46272 | E3: 46279 | F3: 46286 | G3: 46293 | H3: 46300 | I3: 46307 | J3: 46314 | K3: 46321 | L3: 46328 | M3: 46335 | N3: 46342 | O3: 46349 | P3: 46356 | Q3: 46363 | R3: 46370 | S3: 46377 | T3: 46384
A4: A1 | B4: Solicitar a Navantia el protocolo de su IdP (SAML/ADFS u OIDC/Azure AD) | C4: Full Stack Developer | D4: =IF(AND('Plan de tareas'!$H$5<=DATE(2026,9,13),'Plan de tareas'!$I$5>=DATE(2026,9,7)),1,0) -> 1 | E4: =IF(AND('Plan de tareas'!$H$5<=DATE(2026,9,20),'Plan de tareas'!$I$5>=DATE(2026,9,14)),1,0) -> 0 | F4: =IF(AND('Plan de tareas'!$H$5<=DATE(2026,9,27),'Plan de tareas'!$I$5>=DATE(2026,9,21)),1,0) -> 0 | G4: =IF(AND('Plan de tareas'!$H$5<=DATE(2026,10,4),'Plan de tareas'!$I$5>=DATE(2026,9,28)),1,0) -> 0 | H4: =IF(AND('Plan de tareas'!$H$5<=DATE(2026,10,11),'Plan de tareas'!$I$5>=DATE(2026,10,5)),1,0) -> 0 | I4: =IF(AND('Plan de tareas'!$H$5<=DATE(2026,10,18),'Plan de tareas'!$I$5>=DATE(2026,10,12)),1,0) -> 0 | J4: =IF(AND('Plan de tareas'!$H$5<=DATE(2026,10,25),'Plan de tareas'!$I$5>=DATE(2026,10,19)),1,0) -> 0 | K4: =IF(AND('Plan de tareas'!$H$5<=DATE(2026,11,1),'Plan de tareas'!$I$5>=DATE(2026,10,26)),1,0) -> 0 | L4: =IF(AND('Plan de tareas'!$H$5<=DATE(2026,11,8),'Plan de tareas'!$I$5>=DATE(2026,11,2)),1,0) -> 0 | M4: =IF(AND('Plan de tareas'!$H$5<=DATE(2026,11,15),'Plan de tareas'!$I$5>=DATE(2026,11,9)),1,0) -> 0 | N4: =IF(AND('Plan de tareas'!$H$5<=DATE(2026,11,22),'Plan de tareas'!$I$5>=DATE(2026,11,16)),1,0) -> 0 | O4: =IF(AND('Plan de tareas'!$H$5<=DATE(2026,11,29),'Plan de tareas'!$I$5>=DATE(2026,11,23)),1,0) -> 0 | P4: =IF(AND('Plan de tareas'!$H$5<=DATE(2026,12,6),'Plan de tareas'!$I$5>=DATE(2026,11,30)),1,0) -> 0 | Q4: =IF(AND('Plan de tareas'!$H$5<=DATE(2026,12,13),'Plan de tareas'!$I$5>=DATE(2026,12,7)),1,0) -> 0 | R4: =IF(AND('Plan de tareas'!$H$5<=DATE(2026,12,20),'Plan de tareas'!$I$5>=DATE(2026,12,14)),1,0) -> 0 | S4: =IF(AND('Plan de tareas'!$H$5<=DATE(2026,12,27),'Plan de tareas'!$I$5>=DATE(2026,12,21)),1,0) -> 0 | T4: =IF(AND('Plan de tareas'!$H$5<=DATE(2027,1,3),'Plan de tareas'!$I$5>=DATE(2026,12,28)),1,0) -> 0
A5: A2 | B5: Solicitar a seguridad/compliance ATEXIS: tier aacf (T1-T4), guardrails G1-G12 exigibles, restricciones onshore/offshore, y si el aislamiento por proyecto (decisión A) es control suficiente por sí solo | C5: Full Stack Developer | D5: =IF(AND('Plan de tareas'!$H$6<=DATE(2026,9,13),'Plan de tareas'!$I$6>=DATE(2026,9,7)),1,0) -> 1 | E5: =IF(AND('Plan de tareas'!$H$6<=DATE(2026,9,20),'Plan de tareas'!$I$6>=DATE(2026,9,14)),1,0) -> 0 | F5: =IF(AND('Plan de tareas'!$H$6<=DATE(2026,9,27),'Plan de tareas'!$I$6>=DATE(2026,9,21)),1,0) -> 0 | G5: =IF(AND('Plan de tareas'!$H$6<=DATE(2026,10,4),'Plan de tareas'!$I$6>=DATE(2026,9,28)),1,0) -> 0 | H5: =IF(AND('Plan de tareas'!$H$6<=DATE(2026,10,11),'Plan de tareas'!$I$6>=DATE(2026,10,5)),1,0) -> 0 | I5: =IF(AND('Plan de tareas'!$H$6<=DATE(2026,10,18),'Plan de tareas'!$I$6>=DATE(2026,10,12)),1,0) -> 0 | J5: =IF(AND('Plan de tareas'!$H$6<=DATE(2026,10,25),'Plan de tareas'!$I$6>=DATE(2026,10,19)),1,0) -> 0 | K5: =IF(AND('Plan de tareas'!$H$6<=DATE(2026,11,1),'Plan de tareas'!$I$6>=DATE(2026,10,26)),1,0) -> 0 | L5: =IF(AND('Plan de tareas'!$H$6<=DATE(2026,11,8),'Plan de tareas'!$I$6>=DATE(2026,11,2)),1,0) -> 0 | M5: =IF(AND('Plan de tareas'!$H$6<=DATE(2026,11,15),'Plan de tareas'!$I$6>=DATE(2026,11,9)),1,0) -> 0 | N5: =IF(AND('Plan de tareas'!$H$6<=DATE(2026,11,22),'Plan de tareas'!$I$6>=DATE(2026,11,16)),1,0) -> 0 | O5: =IF(AND('Plan de tareas'!$H$6<=DATE(2026,11,29),'Plan de tareas'!$I$6>=DATE(2026,11,23)),1,0) -> 0 | P5: =IF(AND('Plan de tareas'!$H$6<=DATE(2026,12,6),'Plan de tareas'!$I$6>=DATE(2026,11,30)),1,0) -> 0 | Q5: =IF(AND('Plan de tareas'!$H$6<=DATE(2026,12,13),'Plan de tareas'!$I$6>=DATE(2026,12,7)),1,0) -> 0 | R5: =IF(AND('Plan de tareas'!$H$6<=DATE(2026,12,20),'Plan de tareas'!$I$6>=DATE(2026,12,14)),1,0) -> 0 | S5: =IF(AND('Plan de tareas'!$H$6<=DATE(2026,12,27),'Plan de tareas'!$I$6>=DATE(2026,12,21)),1,0) -> 0 | T5: =IF(AND('Plan de tareas'!$H$6<=DATE(2027,1,3),'Plan de tareas'!$I$6>=DATE(2026,12,28)),1,0) -> 0
A6: A3 | B6: Cerrar con negocio/Navantia la lista definitiva de roles RBAC | C6: Full Stack Developer | D6: =IF(AND('Plan de tareas'!$H$7<=DATE(2026,9,13),'Plan de tareas'!$I$7>=DATE(2026,9,7)),1,0) -> 1 | E6: =IF(AND('Plan de tareas'!$H$7<=DATE(2026,9,20),'Plan de tareas'!$I$7>=DATE(2026,9,14)),1,0) -> 0 | F6: =IF(AND('Plan de tareas'!$H$7<=DATE(2026,9,27),'Plan de tareas'!$I$7>=DATE(2026,9,21)),1,0) -> 0 | G6: =IF(AND('Plan de tareas'!$H$7<=DATE(2026,10,4),'Plan de tareas'!$I$7>=DATE(2026,9,28)),1,0) -> 0 | H6: =IF(AND('Plan de tareas'!$H$7<=DATE(2026,10,11),'Plan de tareas'!$I$7>=DATE(2026,10,5)),1,0) -> 0 | I6: =IF(AND('Plan de tareas'!$H$7<=DATE(2026,10,18),'Plan de tareas'!$I$7>=DATE(2026,10,12)),1,0) -> 0 | J6: =IF(AND('Plan de tareas'!$H$7<=DATE(2026,10,25),'Plan de tareas'!$I$7>=DATE(2026,10,19)),1,0) -> 0 | K6: =IF(AND('Plan de tareas'!$H$7<=DATE(2026,11,1),'Plan de tareas'!$I$7>=DATE(2026,10,26)),1,0) -> 0 | L6: =IF(AND('Plan de tareas'!$H$7<=DATE(2026,11,8),'Plan de tareas'!$I$7>=DATE(2026,11,2)),1,0) -> 0 | M6: =IF(AND('Plan de tareas'!$H$7<=DATE(2026,11,15),'Plan de tareas'!$I$7>=DATE(2026,11,9)),1,0) -> 0 | N6: =IF(AND('Plan de tareas'!$H$7<=DATE(2026,11,22),'Plan de tareas'!$I$7>=DATE(2026,11,16)),1,0) -> 0 | O6: =IF(AND('Plan de tareas'!$H$7<=DATE(2026,11,29),'Plan de tareas'!$I$7>=DATE(2026,11,23)),1,0) -> 0 | P6: =IF(AND('Plan de tareas'!$H$7<=DATE(2026,12,6),'Plan de tareas'!$I$7>=DATE(2026,11,30)),1,0) -> 0 | Q6: =IF(AND('Plan de tareas'!$H$7<=DATE(2026,12,13),'Plan de tareas'!$I$7>=DATE(2026,12,7)),1,0) -> 0 | R6: =IF(AND('Plan de tareas'!$H$7<=DATE(2026,12,20),'Plan de tareas'!$I$7>=DATE(2026,12,14)),1,0) -> 0 | S6: =IF(AND('Plan de tareas'!$H$7<=DATE(2026,12,27),'Plan de tareas'!$I$7>=DATE(2026,12,21)),1,0) -> 0 | T6: =IF(AND('Plan de tareas'!$H$7<=DATE(2027,1,3),'Plan de tareas'!$I$7>=DATE(2026,12,28)),1,0) -> 0
A7: A4 | B7: Confirmar alcance del worker de publicación: ¿RenderX + Compositor S80 desde el inicio, o solo Compositor S80? | C7: Full Stack Developer | D7: =IF(AND('Plan de tareas'!$H$8<=DATE(2026,9,13),'Plan de tareas'!$I$8>=DATE(2026,9,7)),1,0) -> 1 | E7: =IF(AND('Plan de tareas'!$H$8<=DATE(2026,9,20),'Plan de tareas'!$I$8>=DATE(2026,9,14)),1,0) -> 0 | F7: =IF(AND('Plan de tareas'!$H$8<=DATE(2026,9,27),'Plan de tareas'!$I$8>=DATE(2026,9,21)),1,0) -> 0 | G7: =IF(AND('Plan de tareas'!$H$8<=DATE(2026,10,4),'Plan de tareas'!$I$8>=DATE(2026,9,28)),1,0) -> 0 | H7: =IF(AND('Plan de tareas'!$H$8<=DATE(2026,10,11),'Plan de tareas'!$I$8>=DATE(2026,10,5)),1,0) -> 0 | I7: =IF(AND('Plan de tareas'!$H$8<=DATE(2026,10,18),'Plan de tareas'!$I$8>=DATE(2026,10,12)),1,0) -> 0 | J7: =IF(AND('Plan de tareas'!$H$8<=DATE(2026,10,25),'Plan de tareas'!$I$8>=DATE(2026,10,19)),1,0) -> 0 | K7: =IF(AND('Plan de tareas'!$H$8<=DATE(2026,11,1),'Plan de tareas'!$I$8>=DATE(2026,10,26)),1,0) -> 0 | L7: =IF(AND('Plan de tareas'!$H$8<=DATE(2026,11,8),'Plan de tareas'!$I$8>=DATE(2026,11,2)),1,0) -> 0 | M7: =IF(AND('Plan de tareas'!$H$8<=DATE(2026,11,15),'Plan de tareas'!$I$8>=DATE(2026,11,9)),1,0) -> 0 | N7: =IF(AND('Plan de tareas'!$H$8<=DATE(2026,11,22),'Plan de tareas'!$I$8>=DATE(2026,11,16)),1,0) -> 0 | O7: =IF(AND('Plan de tareas'!$H$8<=DATE(2026,11,29),'Plan de tareas'!$I$8>=DATE(2026,11,23)),1,0) -> 0 | P7: =IF(AND('Plan de tareas'!$H$8<=DATE(2026,12,6),'Plan de tareas'!$I$8>=DATE(2026,11,30)),1,0) -> 0 | Q7: =IF(AND('Plan de tareas'!$H$8<=DATE(2026,12,13),'Plan de tareas'!$I$8>=DATE(2026,12,7)),1,0) -> 0 | R7: =IF(AND('Plan de tareas'!$H$8<=DATE(2026,12,20),'Plan de tareas'!$I$8>=DATE(2026,12,14)),1,0) -> 0 | S7: =IF(AND('Plan de tareas'!$H$8<=DATE(2026,12,27),'Plan de tareas'!$I$8>=DATE(2026,12,21)),1,0) -> 0 | T7: =IF(AND('Plan de tareas'!$H$8<=DATE(2027,1,3),'Plan de tareas'!$I$8>=DATE(2026,12,28)),1,0) -> 0
A8: A5 | B8: Decidir si se activa eXist-db en este build o se pospone | C8: Full Stack Developer | D8: =IF(AND('Plan de tareas'!$H$9<=DATE(2026,9,13),'Plan de tareas'!$I$9>=DATE(2026,9,7)),1,0) -> 1 | E8: =IF(AND('Plan de tareas'!$H$9<=DATE(2026,9,20),'Plan de tareas'!$I$9>=DATE(2026,9,14)),1,0) -> 0 | F8: =IF(AND('Plan de tareas'!$H$9<=DATE(2026,9,27),'Plan de tareas'!$I$9>=DATE(2026,9,21)),1,0) -> 0 | G8: =IF(AND('Plan de tareas'!$H$9<=DATE(2026,10,4),'Plan de tareas'!$I$9>=DATE(2026,9,28)),1,0) -> 0 | H8: =IF(AND('Plan de tareas'!$H$9<=DATE(2026,10,11),'Plan de tareas'!$I$9>=DATE(2026,10,5)),1,0) -> 0 | I8: =IF(AND('Plan de tareas'!$H$9<=DATE(2026,10,18),'Plan de tareas'!$I$9>=DATE(2026,10,12)),1,0) -> 0 | J8: =IF(AND('Plan de tareas'!$H$9<=DATE(2026,10,25),'Plan de tareas'!$I$9>=DATE(2026,10,19)),1,0) -> 0 | K8: =IF(AND('Plan de tareas'!$H$9<=DATE(2026,11,1),'Plan de tareas'!$I$9>=DATE(2026,10,26)),1,0) -> 0 | L8: =IF(AND('Plan de tareas'!$H$9<=DATE(2026,11,8),'Plan de tareas'!$I$9>=DATE(2026,11,2)),1,0) -> 0 | M8: =IF(AND('Plan de tareas'!$H$9<=DATE(2026,11,15),'Plan de tareas'!$I$9>=DATE(2026,11,9)),1,0) -> 0 | N8: =IF(AND('Plan de tareas'!$H$9<=DATE(2026,11,22),'Plan de tareas'!$I$9>=DATE(2026,11,16)),1,0) -> 0 | O8: =IF(AND('Plan de tareas'!$H$9<=DATE(2026,11,29),'Plan de tareas'!$I$9>=DATE(2026,11,23)),1,0) -> 0 | P8: =IF(AND('Plan de tareas'!$H$9<=DATE(2026,12,6),'Plan de tareas'!$I$9>=DATE(2026,11,30)),1,0) -> 0 | Q8: =IF(AND('Plan de tareas'!$H$9<=DATE(2026,12,13),'Plan de tareas'!$I$9>=DATE(2026,12,7)),1,0) -> 0 | R8: =IF(AND('Plan de tareas'!$H$9<=DATE(2026,12,20),'Plan de tareas'!$I$9>=DATE(2026,12,14)),1,0) -> 0 | S8: =IF(AND('Plan de tareas'!$H$9<=DATE(2026,12,27),'Plan de tareas'!$I$9>=DATE(2026,12,21)),1,0) -> 0 | T8: =IF(AND('Plan de tareas'!$H$9<=DATE(2027,1,3),'Plan de tareas'!$I$9>=DATE(2026,12,28)),1,0) -> 0
A9: B1 | B9: docker-compose.yml real + .env dev (PostgreSQL + OpenSearch) | C9: Full Stack Developer | D9: =IF(AND('Plan de tareas'!$H$10<=DATE(2026,9,13),'Plan de tareas'!$I$10>=DATE(2026,9,7)),1,0) -> 1 | E9: =IF(AND('Plan de tareas'!$H$10<=DATE(2026,9,20),'Plan de tareas'!$I$10>=DATE(2026,9,14)),1,0) -> 0 | F9: =IF(AND('Plan de tareas'!$H$10<=DATE(2026,9,27),'Plan de tareas'!$I$10>=DATE(2026,9,21)),1,0) -> 0 | G9: =IF(AND('Plan de tareas'!$H$10<=DATE(2026,10,4),'Plan de tareas'!$I$10>=DATE(2026,9,28)),1,0) -> 0 | H9: =IF(AND('Plan de tareas'!$H$10<=DATE(2026,10,11),'Plan de tareas'!$I$10>=DATE(2026,10,5)),1,0) -> 0 | I9: =IF(AND('Plan de tareas'!$H$10<=DATE(2026,10,18),'Plan de tareas'!$I$10>=DATE(2026,10,12)),1,0) -> 0 | J9: =IF(AND('Plan de tareas'!$H$10<=DATE(2026,10,25),'Plan de tareas'!$I$10>=DATE(2026,10,19)),1,0) -> 0 | K9: =IF(AND('Plan de tareas'!$H$10<=DATE(2026,11,1),'Plan de tareas'!$I$10>=DATE(2026,10,26)),1,0) -> 0 | L9: =IF(AND('Plan de tareas'!$H$10<=DATE(2026,11,8),'Plan de tareas'!$I$10>=DATE(2026,11,2)),1,0) -> 0 | M9: =IF(AND('Plan de tareas'!$H$10<=DATE(2026,11,15),'Plan de tareas'!$I$10>=DATE(2026,11,9)),1,0) -> 0 | N9: =IF(AND('Plan de tareas'!$H$10<=DATE(2026,11,22),'Plan de tareas'!$I$10>=DATE(2026,11,16)),1,0) -> 0 | O9: =IF(AND('Plan de tareas'!$H$10<=DATE(2026,11,29),'Plan de tareas'!$I$10>=DATE(2026,11,23)),1,0) -> 0 | P9: =IF(AND('Plan de tareas'!$H$10<=DATE(2026,12,6),'Plan de tareas'!$I$10>=DATE(2026,11,30)),1,0) -> 0 | Q9: =IF(AND('Plan de tareas'!$H$10<=DATE(2026,12,13),'Plan de tareas'!$I$10>=DATE(2026,12,7)),1,0) -> 0 | R9: =IF(AND('Plan de tareas'!$H$10<=DATE(2026,12,20),'Plan de tareas'!$I$10>=DATE(2026,12,14)),1,0) -> 0 | S9: =IF(AND('Plan de tareas'!$H$10<=DATE(2026,12,27),'Plan de tareas'!$I$10>=DATE(2026,12,21)),1,0) -> 0 | T9: =IF(AND('Plan de tareas'!$H$10<=DATE(2027,1,3),'Plan de tareas'!$I$10>=DATE(2026,12,28)),1,0) -> 0
A10: B2 | B10: Aplicar el esquema de PostgreSQL (9 tablas base + proyecto + catálogo RBAC + tareas/comentarios/auditoría + 7 tablas del índice de extracción) | C10: Full Stack Developer | D10: =IF(AND('Plan de tareas'!$H$11<=DATE(2026,9,13),'Plan de tareas'!$I$11>=DATE(2026,9,7)),1,0) -> 1 | E10: =IF(AND('Plan de tareas'!$H$11<=DATE(2026,9,20),'Plan de tareas'!$I$11>=DATE(2026,9,14)),1,0) -> 0 | F10: =IF(AND('Plan de tareas'!$H$11<=DATE(2026,9,27),'Plan de tareas'!$I$11>=DATE(2026,9,21)),1,0) -> 0 | G10: =IF(AND('Plan de tareas'!$H$11<=DATE(2026,10,4),'Plan de tareas'!$I$11>=DATE(2026,9,28)),1,0) -> 0 | H10: =IF(AND('Plan de tareas'!$H$11<=DATE(2026,10,11),'Plan de tareas'!$I$11>=DATE(2026,10,5)),1,0) -> 0 | I10: =IF(AND('Plan de tareas'!$H$11<=DATE(2026,10,18),'Plan de tareas'!$I$11>=DATE(2026,10,12)),1,0) -> 0 | J10: =IF(AND('Plan de tareas'!$H$11<=DATE(2026,10,25),'Plan de tareas'!$I$11>=DATE(2026,10,19)),1,0) -> 0 | K10: =IF(AND('Plan de tareas'!$H$11<=DATE(2026,11,1),'Plan de tareas'!$I$11>=DATE(2026,10,26)),1,0) -> 0 | L10: =IF(AND('Plan de tareas'!$H$11<=DATE(2026,11,8),'Plan de tareas'!$I$11>=DATE(2026,11,2)),1,0) -> 0 | M10: =IF(AND('Plan de tareas'!$H$11<=DATE(2026,11,15),'Plan de tareas'!$I$11>=DATE(2026,11,9)),1,0) -> 0 | N10: =IF(AND('Plan de tareas'!$H$11<=DATE(2026,11,22),'Plan de tareas'!$I$11>=DATE(2026,11,16)),1,0) -> 0 | O10: =IF(AND('Plan de tareas'!$H$11<=DATE(2026,11,29),'Plan de tareas'!$I$11>=DATE(2026,11,23)),1,0) -> 0 | P10: =IF(AND('Plan de tareas'!$H$11<=DATE(2026,12,6),'Plan de tareas'!$I$11>=DATE(2026,11,30)),1,0) -> 0 | Q10: =IF(AND('Plan de tareas'!$H$11<=DATE(2026,12,13),'Plan de tareas'!$I$11>=DATE(2026,12,7)),1,0) -> 0 | R10: =IF(AND('Plan de tareas'!$H$11<=DATE(2026,12,20),'Plan de tareas'!$I$11>=DATE(2026,12,14)),1,0) -> 0 | S10: =IF(AND('Plan de tareas'!$H$11<=DATE(2026,12,27),'Plan de tareas'!$I$11>=DATE(2026,12,21)),1,0) -> 0 | T10: =IF(AND('Plan de tareas'!$H$11<=DATE(2027,1,3),'Plan de tareas'!$I$11>=DATE(2026,12,28)),1,0) -> 0
A11: B3 | B11: core/config.py | C11: Full Stack Developer | D11: =IF(AND('Plan de tareas'!$H$12<=DATE(2026,9,13),'Plan de tareas'!$I$12>=DATE(2026,9,7)),1,0) -> 1 | E11: =IF(AND('Plan de tareas'!$H$12<=DATE(2026,9,20),'Plan de tareas'!$I$12>=DATE(2026,9,14)),1,0) -> 0 | F11: =IF(AND('Plan de tareas'!$H$12<=DATE(2026,9,27),'Plan de tareas'!$I$12>=DATE(2026,9,21)),1,0) -> 0 | G11: =IF(AND('Plan de tareas'!$H$12<=DATE(2026,10,4),'Plan de tareas'!$I$12>=DATE(2026,9,28)),1,0) -> 0 | H11: =IF(AND('Plan de tareas'!$H$12<=DATE(2026,10,11),'Plan de tareas'!$I$12>=DATE(2026,10,5)),1,0) -> 0 | I11: =IF(AND('Plan de tareas'!$H$12<=DATE(2026,10,18),'Plan de tareas'!$I$12>=DATE(2026,10,12)),1,0) -> 0 | J11: =IF(AND('Plan de tareas'!$H$12<=DATE(2026,10,25),'Plan de tareas'!$I$12>=DATE(2026,10,19)),1,0) -> 0 | K11: =IF(AND('Plan de tareas'!$H$12<=DATE(2026,11,1),'Plan de tareas'!$I$12>=DATE(2026,10,26)),1,0) -> 0 | L11: =IF(AND('Plan de tareas'!$H$12<=DATE(2026,11,8),'Plan de tareas'!$I$12>=DATE(2026,11,2)),1,0) -> 0 | M11: =IF(AND('Plan de tareas'!$H$12<=DATE(2026,11,15),'Plan de tareas'!$I$12>=DATE(2026,11,9)),1,0) -> 0 | N11: =IF(AND('Plan de tareas'!$H$12<=DATE(2026,11,22),'Plan de tareas'!$I$12>=DATE(2026,11,16)),1,0) -> 0 | O11: =IF(AND('Plan de tareas'!$H$12<=DATE(2026,11,29),'Plan de tareas'!$I$12>=DATE(2026,11,23)),1,0) -> 0 | P11: =IF(AND('Plan de tareas'!$H$12<=DATE(2026,12,6),'Plan de tareas'!$I$12>=DATE(2026,11,30)),1,0) -> 0 | Q11: =IF(AND('Plan de tareas'!$H$12<=DATE(2026,12,13),'Plan de tareas'!$I$12>=DATE(2026,12,7)),1,0) -> 0 | R11: =IF(AND('Plan de tareas'!$H$12<=DATE(2026,12,20),'Plan de tareas'!$I$12>=DATE(2026,12,14)),1,0) -> 0 | S11: =IF(AND('Plan de tareas'!$H$12<=DATE(2026,12,27),'Plan de tareas'!$I$12>=DATE(2026,12,21)),1,0) -> 0 | T11: =IF(AND('Plan de tareas'!$H$12<=DATE(2027,1,3),'Plan de tareas'!$I$12>=DATE(2026,12,28)),1,0) -> 0
A12: B4 | B12: Catálogo RBAC: tablas + datos semilla provisionales | C12: Full Stack Developer | D12: =IF(AND('Plan de tareas'!$H$13<=DATE(2026,9,13),'Plan de tareas'!$I$13>=DATE(2026,9,7)),1,0) -> 1 | E12: =IF(AND('Plan de tareas'!$H$13<=DATE(2026,9,20),'Plan de tareas'!$I$13>=DATE(2026,9,14)),1,0) -> 0 | F12: =IF(AND('Plan de tareas'!$H$13<=DATE(2026,9,27),'Plan de tareas'!$I$13>=DATE(2026,9,21)),1,0) -> 0 | G12: =IF(AND('Plan de tareas'!$H$13<=DATE(2026,10,4),'Plan de tareas'!$I$13>=DATE(2026,9,28)),1,0) -> 0 | H12: =IF(AND('Plan de tareas'!$H$13<=DATE(2026,10,11),'Plan de tareas'!$I$13>=DATE(2026,10,5)),1,0) -> 0 | I12: =IF(AND('Plan de tareas'!$H$13<=DATE(2026,10,18),'Plan de tareas'!$I$13>=DATE(2026,10,12)),1,0) -> 0 | J12: =IF(AND('Plan de tareas'!$H$13<=DATE(2026,10,25),'Plan de tareas'!$I$13>=DATE(2026,10,19)),1,0) -> 0 | K12: =IF(AND('Plan de tareas'!$H$13<=DATE(2026,11,1),'Plan de tareas'!$I$13>=DATE(2026,10,26)),1,0) -> 0 | L12: =IF(AND('Plan de tareas'!$H$13<=DATE(2026,11,8),'Plan de tareas'!$I$13>=DATE(2026,11,2)),1,0) -> 0 | M12: =IF(AND('Plan de tareas'!$H$13<=DATE(2026,11,15),'Plan de tareas'!$I$13>=DATE(2026,11,9)),1,0) -> 0 | N12: =IF(AND('Plan de tareas'!$H$13<=DATE(2026,11,22),'Plan de tareas'!$I$13>=DATE(2026,11,16)),1,0) -> 0 | O12: =IF(AND('Plan de tareas'!$H$13<=DATE(2026,11,29),'Plan de tareas'!$I$13>=DATE(2026,11,23)),1,0) -> 0 | P12: =IF(AND('Plan de tareas'!$H$13<=DATE(2026,12,6),'Plan de tareas'!$I$13>=DATE(2026,11,30)),1,0) -> 0 | Q12: =IF(AND('Plan de tareas'!$H$13<=DATE(2026,12,13),'Plan de tareas'!$I$13>=DATE(2026,12,7)),1,0) -> 0 | R12: =IF(AND('Plan de tareas'!$H$13<=DATE(2026,12,20),'Plan de tareas'!$I$13>=DATE(2026,12,14)),1,0) -> 0 | S12: =IF(AND('Plan de tareas'!$H$13<=DATE(2026,12,27),'Plan de tareas'!$I$13>=DATE(2026,12,21)),1,0) -> 0 | T12: =IF(AND('Plan de tareas'!$H$13<=DATE(2027,1,3),'Plan de tareas'!$I$13>=DATE(2026,12,28)),1,0) -> 0
A13: B5 | B13: core/seguridad.py — dependencia FastAPI de JWT + RBAC | C13: Full Stack Developer | D13: =IF(AND('Plan de tareas'!$H$14<=DATE(2026,9,13),'Plan de tareas'!$I$14>=DATE(2026,9,7)),1,0) -> 1 | E13: =IF(AND('Plan de tareas'!$H$14<=DATE(2026,9,20),'Plan de tareas'!$I$14>=DATE(2026,9,14)),1,0) -> 1 | F13: =IF(AND('Plan de tareas'!$H$14<=DATE(2026,9,27),'Plan de tareas'!$I$14>=DATE(2026,9,21)),1,0) -> 0 | G13: =IF(AND('Plan de tareas'!$H$14<=DATE(2026,10,4),'Plan de tareas'!$I$14>=DATE(2026,9,28)),1,0) -> 0 | H13: =IF(AND('Plan de tareas'!$H$14<=DATE(2026,10,11),'Plan de tareas'!$I$14>=DATE(2026,10,5)),1,0) -> 0 | I13: =IF(AND('Plan de tareas'!$H$14<=DATE(2026,10,18),'Plan de tareas'!$I$14>=DATE(2026,10,12)),1,0) -> 0 | J13: =IF(AND('Plan de tareas'!$H$14<=DATE(2026,10,25),'Plan de tareas'!$I$14>=DATE(2026,10,19)),1,0) -> 0 | K13: =IF(AND('Plan de tareas'!$H$14<=DATE(2026,11,1),'Plan de tareas'!$I$14>=DATE(2026,10,26)),1,0) -> 0 | L13: =IF(AND('Plan de tareas'!$H$14<=DATE(2026,11,8),'Plan de tareas'!$I$14>=DATE(2026,11,2)),1,0) -> 0 | M13: =IF(AND('Plan de tareas'!$H$14<=DATE(2026,11,15),'Plan de tareas'!$I$14>=DATE(2026,11,9)),1,0) -> 0 | N13: =IF(AND('Plan de tareas'!$H$14<=DATE(2026,11,22),'Plan de tareas'!$I$14>=DATE(2026,11,16)),1,0) -> 0 | O13: =IF(AND('Plan de tareas'!$H$14<=DATE(2026,11,29),'Plan de tareas'!$I$14>=DATE(2026,11,23)),1,0) -> 0 | P13: =IF(AND('Plan de tareas'!$H$14<=DATE(2026,12,6),'Plan de tareas'!$I$14>=DATE(2026,11,30)),1,0) -> 0 | Q13: =IF(AND('Plan de tareas'!$H$14<=DATE(2026,12,13),'Plan de tareas'!$I$14>=DATE(2026,12,7)),1,0) -> 0 | R13: =IF(AND('Plan de tareas'!$H$14<=DATE(2026,12,20),'Plan de tareas'!$I$14>=DATE(2026,12,14)),1,0) -> 0 | S13: =IF(AND('Plan de tareas'!$H$14<=DATE(2026,12,27),'Plan de tareas'!$I$14>=DATE(2026,12,21)),1,0) -> 0 | T13: =IF(AND('Plan de tareas'!$H$14<=DATE(2027,1,3),'Plan de tareas'!$I$14>=DATE(2026,12,28)),1,0) -> 0
A14: B6 | B14: core/proyecto_context.py — dependencia FastAPI de aislamiento multi-proyecto/cliente | C14: Full Stack Developer | D14: =IF(AND('Plan de tareas'!$H$15<=DATE(2026,9,13),'Plan de tareas'!$I$15>=DATE(2026,9,7)),1,0) -> 0 | E14: =IF(AND('Plan de tareas'!$H$15<=DATE(2026,9,20),'Plan de tareas'!$I$15>=DATE(2026,9,14)),1,0) -> 1 | F14: =IF(AND('Plan de tareas'!$H$15<=DATE(2026,9,27),'Plan de tareas'!$I$15>=DATE(2026,9,21)),1,0) -> 0 | G14: =IF(AND('Plan de tareas'!$H$15<=DATE(2026,10,4),'Plan de tareas'!$I$15>=DATE(2026,9,28)),1,0) -> 0 | H14: =IF(AND('Plan de tareas'!$H$15<=DATE(2026,10,11),'Plan de tareas'!$I$15>=DATE(2026,10,5)),1,0) -> 0 | I14: =IF(AND('Plan de tareas'!$H$15<=DATE(2026,10,18),'Plan de tareas'!$I$15>=DATE(2026,10,12)),1,0) -> 0 | J14: =IF(AND('Plan de tareas'!$H$15<=DATE(2026,10,25),'Plan de tareas'!$I$15>=DATE(2026,10,19)),1,0) -> 0 | K14: =IF(AND('Plan de tareas'!$H$15<=DATE(2026,11,1),'Plan de tareas'!$I$15>=DATE(2026,10,26)),1,0) -> 0 | L14: =IF(AND('Plan de tareas'!$H$15<=DATE(2026,11,8),'Plan de tareas'!$I$15>=DATE(2026,11,2)),1,0) -> 0 | M14: =IF(AND('Plan de tareas'!$H$15<=DATE(2026,11,15),'Plan de tareas'!$I$15>=DATE(2026,11,9)),1,0) -> 0 | N14: =IF(AND('Plan de tareas'!$H$15<=DATE(2026,11,22),'Plan de tareas'!$I$15>=DATE(2026,11,16)),1,0) -> 0 | O14: =IF(AND('Plan de tareas'!$H$15<=DATE(2026,11,29),'Plan de tareas'!$I$15>=DATE(2026,11,23)),1,0) -> 0 | P14: =IF(AND('Plan de tareas'!$H$15<=DATE(2026,12,6),'Plan de tareas'!$I$15>=DATE(2026,11,30)),1,0) -> 0 | Q14: =IF(AND('Plan de tareas'!$H$15<=DATE(2026,12,13),'Plan de tareas'!$I$15>=DATE(2026,12,7)),1,0) -> 0 | R14: =IF(AND('Plan de tareas'!$H$15<=DATE(2026,12,20),'Plan de tareas'!$I$15>=DATE(2026,12,14)),1,0) -> 0 | S14: =IF(AND('Plan de tareas'!$H$15<=DATE(2026,12,27),'Plan de tareas'!$I$15>=DATE(2026,12,21)),1,0) -> 0 | T14: =IF(AND('Plan de tareas'!$H$15<=DATE(2027,1,3),'Plan de tareas'!$I$15>=DATE(2026,12,28)),1,0) -> 0
A15: B7 | B15: auth/federacion.py + adaptador IdP ATEXIS/Keycloak | C15: Full Stack Developer | D15: =IF(AND('Plan de tareas'!$H$16<=DATE(2026,9,13),'Plan de tareas'!$I$16>=DATE(2026,9,7)),1,0) -> 0 | E15: =IF(AND('Plan de tareas'!$H$16<=DATE(2026,9,20),'Plan de tareas'!$I$16>=DATE(2026,9,14)),1,0) -> 1 | F15: =IF(AND('Plan de tareas'!$H$16<=DATE(2026,9,27),'Plan de tareas'!$I$16>=DATE(2026,9,21)),1,0) -> 0 | G15: =IF(AND('Plan de tareas'!$H$16<=DATE(2026,10,4),'Plan de tareas'!$I$16>=DATE(2026,9,28)),1,0) -> 0 | H15: =IF(AND('Plan de tareas'!$H$16<=DATE(2026,10,11),'Plan de tareas'!$I$16>=DATE(2026,10,5)),1,0) -> 0 | I15: =IF(AND('Plan de tareas'!$H$16<=DATE(2026,10,18),'Plan de tareas'!$I$16>=DATE(2026,10,12)),1,0) -> 0 | J15: =IF(AND('Plan de tareas'!$H$16<=DATE(2026,10,25),'Plan de tareas'!$I$16>=DATE(2026,10,19)),1,0) -> 0 | K15: =IF(AND('Plan de tareas'!$H$16<=DATE(2026,11,1),'Plan de tareas'!$I$16>=DATE(2026,10,26)),1,0) -> 0 | L15: =IF(AND('Plan de tareas'!$H$16<=DATE(2026,11,8),'Plan de tareas'!$I$16>=DATE(2026,11,2)),1,0) -> 0 | M15: =IF(AND('Plan de tareas'!$H$16<=DATE(2026,11,15),'Plan de tareas'!$I$16>=DATE(2026,11,9)),1,0) -> 0 | N15: =IF(AND('Plan de tareas'!$H$16<=DATE(2026,11,22),'Plan de tareas'!$I$16>=DATE(2026,11,16)),1,0) -> 0 | O15: =IF(AND('Plan de tareas'!$H$16<=DATE(2026,11,29),'Plan de tareas'!$I$16>=DATE(2026,11,23)),1,0) -> 0 | P15: =IF(AND('Plan de tareas'!$H$16<=DATE(2026,12,6),'Plan de tareas'!$I$16>=DATE(2026,11,30)),1,0) -> 0 | Q15: =IF(AND('Plan de tareas'!$H$16<=DATE(2026,12,13),'Plan de tareas'!$I$16>=DATE(2026,12,7)),1,0) -> 0 | R15: =IF(AND('Plan de tareas'!$H$16<=DATE(2026,12,20),'Plan de tareas'!$I$16>=DATE(2026,12,14)),1,0) -> 0 | S15: =IF(AND('Plan de tareas'!$H$16<=DATE(2026,12,27),'Plan de tareas'!$I$16>=DATE(2026,12,21)),1,0) -> 0 | T15: =IF(AND('Plan de tareas'!$H$16<=DATE(2027,1,3),'Plan de tareas'!$I$16>=DATE(2026,12,28)),1,0) -> 0
A16: B8 | B16: Adaptador IdP Navantia (SAML u OIDC, según respuesta de T-A1) | C16: Full Stack Developer | D16: =IF(AND('Plan de tareas'!$H$17<=DATE(2026,9,13),'Plan de tareas'!$I$17>=DATE(2026,9,7)),1,0) -> 0 | E16: =IF(AND('Plan de tareas'!$H$17<=DATE(2026,9,20),'Plan de tareas'!$I$17>=DATE(2026,9,14)),1,0) -> 1 | F16: =IF(AND('Plan de tareas'!$H$17<=DATE(2026,9,27),'Plan de tareas'!$I$17>=DATE(2026,9,21)),1,0) -> 1 | G16: =IF(AND('Plan de tareas'!$H$17<=DATE(2026,10,4),'Plan de tareas'!$I$17>=DATE(2026,9,28)),1,0) -> 0 | H16: =IF(AND('Plan de tareas'!$H$17<=DATE(2026,10,11),'Plan de tareas'!$I$17>=DATE(2026,10,5)),1,0) -> 0 | I16: =IF(AND('Plan de tareas'!$H$17<=DATE(2026,10,18),'Plan de tareas'!$I$17>=DATE(2026,10,12)),1,0) -> 0 | J16: =IF(AND('Plan de tareas'!$H$17<=DATE(2026,10,25),'Plan de tareas'!$I$17>=DATE(2026,10,19)),1,0) -> 0 | K16: =IF(AND('Plan de tareas'!$H$17<=DATE(2026,11,1),'Plan de tareas'!$I$17>=DATE(2026,10,26)),1,0) -> 0 | L16: =IF(AND('Plan de tareas'!$H$17<=DATE(2026,11,8),'Plan de tareas'!$I$17>=DATE(2026,11,2)),1,0) -> 0 | M16: =IF(AND('Plan de tareas'!$H$17<=DATE(2026,11,15),'Plan de tareas'!$I$17>=DATE(2026,11,9)),1,0) -> 0 | N16: =IF(AND('Plan de tareas'!$H$17<=DATE(2026,11,22),'Plan de tareas'!$I$17>=DATE(2026,11,16)),1,0) -> 0 | O16: =IF(AND('Plan de tareas'!$H$17<=DATE(2026,11,29),'Plan de tareas'!$I$17>=DATE(2026,11,23)),1,0) -> 0 | P16: =IF(AND('Plan de tareas'!$H$17<=DATE(2026,12,6),'Plan de tareas'!$I$17>=DATE(2026,11,30)),1,0) -> 0 | Q16: =IF(AND('Plan de tareas'!$H$17<=DATE(2026,12,13),'Plan de tareas'!$I$17>=DATE(2026,12,7)),1,0) -> 0 | R16: =IF(AND('Plan de tareas'!$H$17<=DATE(2026,12,20),'Plan de tareas'!$I$17>=DATE(2026,12,14)),1,0) -> 0 | S16: =IF(AND('Plan de tareas'!$H$17<=DATE(2026,12,27),'Plan de tareas'!$I$17>=DATE(2026,12,21)),1,0) -> 0 | T16: =IF(AND('Plan de tareas'!$H$17<=DATE(2027,1,3),'Plan de tareas'!$I$17>=DATE(2026,12,28)),1,0) -> 0
A17: C1 | B17: models/ — clases SQLAlchemy de todas las tablas | C17: Full Stack Developer | D17: =IF(AND('Plan de tareas'!$H$18<=DATE(2026,9,13),'Plan de tareas'!$I$18>=DATE(2026,9,7)),1,0) -> 0 | E17: =IF(AND('Plan de tareas'!$H$18<=DATE(2026,9,20),'Plan de tareas'!$I$18>=DATE(2026,9,14)),1,0) -> 0 | F17: =IF(AND('Plan de tareas'!$H$18<=DATE(2026,9,27),'Plan de tareas'!$I$18>=DATE(2026,9,21)),1,0) -> 1 | G17: =IF(AND('Plan de tareas'!$H$18<=DATE(2026,10,4),'Plan de tareas'!$I$18>=DATE(2026,9,28)),1,0) -> 0 | H17: =IF(AND('Plan de tareas'!$H$18<=DATE(2026,10,11),'Plan de tareas'!$I$18>=DATE(2026,10,5)),1,0) -> 0 | I17: =IF(AND('Plan de tareas'!$H$18<=DATE(2026,10,18),'Plan de tareas'!$I$18>=DATE(2026,10,12)),1,0) -> 0 | J17: =IF(AND('Plan de tareas'!$H$18<=DATE(2026,10,25),'Plan de tareas'!$I$18>=DATE(2026,10,19)),1,0) -> 0 | K17: =IF(AND('Plan de tareas'!$H$18<=DATE(2026,11,1),'Plan de tareas'!$I$18>=DATE(2026,10,26)),1,0) -> 0 | L17: =IF(AND('Plan de tareas'!$H$18<=DATE(2026,11,8),'Plan de tareas'!$I$18>=DATE(2026,11,2)),1,0) -> 0 | M17: =IF(AND('Plan de tareas'!$H$18<=DATE(2026,11,15),'Plan de tareas'!$I$18>=DATE(2026,11,9)),1,0) -> 0 | N17: =IF(AND('Plan de tareas'!$H$18<=DATE(2026,11,22),'Plan de tareas'!$I$18>=DATE(2026,11,16)),1,0) -> 0 | O17: =IF(AND('Plan de tareas'!$H$18<=DATE(2026,11,29),'Plan de tareas'!$I$18>=DATE(2026,11,23)),1,0) -> 0 | P17: =IF(AND('Plan de tareas'!$H$18<=DATE(2026,12,6),'Plan de tareas'!$I$18>=DATE(2026,11,30)),1,0) -> 0 | Q17: =IF(AND('Plan de tareas'!$H$18<=DATE(2026,12,13),'Plan de tareas'!$I$18>=DATE(2026,12,7)),1,0) -> 0 | R17: =IF(AND('Plan de tareas'!$H$18<=DATE(2026,12,20),'Plan de tareas'!$I$18>=DATE(2026,12,14)),1,0) -> 0 | S17: =IF(AND('Plan de tareas'!$H$18<=DATE(2026,12,27),'Plan de tareas'!$I$18>=DATE(2026,12,21)),1,0) -> 0 | T17: =IF(AND('Plan de tareas'!$H$18<=DATE(2027,1,3),'Plan de tareas'!$I$18>=DATE(2026,12,28)),1,0) -> 0
A18: C2 | B18: storage/ — 13 módulos de acceso a datos | C18: Full Stack Developer | D18: =IF(AND('Plan de tareas'!$H$19<=DATE(2026,9,13),'Plan de tareas'!$I$19>=DATE(2026,9,7)),1,0) -> 0 | E18: =IF(AND('Plan de tareas'!$H$19<=DATE(2026,9,20),'Plan de tareas'!$I$19>=DATE(2026,9,14)),1,0) -> 0 | F18: =IF(AND('Plan de tareas'!$H$19<=DATE(2026,9,27),'Plan de tareas'!$I$19>=DATE(2026,9,21)),1,0) -> 1 | G18: =IF(AND('Plan de tareas'!$H$19<=DATE(2026,10,4),'Plan de tareas'!$I$19>=DATE(2026,9,28)),1,0) -> 1 | H18: =IF(AND('Plan de tareas'!$H$19<=DATE(2026,10,11),'Plan de tareas'!$I$19>=DATE(2026,10,5)),1,0) -> 0 | I18: =IF(AND('Plan de tareas'!$H$19<=DATE(2026,10,18),'Plan de tareas'!$I$19>=DATE(2026,10,12)),1,0) -> 0 | J18: =IF(AND('Plan de tareas'!$H$19<=DATE(2026,10,25),'Plan de tareas'!$I$19>=DATE(2026,10,19)),1,0) -> 0 | K18: =IF(AND('Plan de tareas'!$H$19<=DATE(2026,11,1),'Plan de tareas'!$I$19>=DATE(2026,10,26)),1,0) -> 0 | L18: =IF(AND('Plan de tareas'!$H$19<=DATE(2026,11,8),'Plan de tareas'!$I$19>=DATE(2026,11,2)),1,0) -> 0 | M18: =IF(AND('Plan de tareas'!$H$19<=DATE(2026,11,15),'Plan de tareas'!$I$19>=DATE(2026,11,9)),1,0) -> 0 | N18: =IF(AND('Plan de tareas'!$H$19<=DATE(2026,11,22),'Plan de tareas'!$I$19>=DATE(2026,11,16)),1,0) -> 0 | O18: =IF(AND('Plan de tareas'!$H$19<=DATE(2026,11,29),'Plan de tareas'!$I$19>=DATE(2026,11,23)),1,0) -> 0 | P18: =IF(AND('Plan de tareas'!$H$19<=DATE(2026,12,6),'Plan de tareas'!$I$19>=DATE(2026,11,30)),1,0) -> 0 | Q18: =IF(AND('Plan de tareas'!$H$19<=DATE(2026,12,13),'Plan de tareas'!$I$19>=DATE(2026,12,7)),1,0) -> 0 | R18: =IF(AND('Plan de tareas'!$H$19<=DATE(2026,12,20),'Plan de tareas'!$I$19>=DATE(2026,12,14)),1,0) -> 0 | S18: =IF(AND('Plan de tareas'!$H$19<=DATE(2026,12,27),'Plan de tareas'!$I$19>=DATE(2026,12,21)),1,0) -> 0 | T18: =IF(AND('Plan de tareas'!$H$19<=DATE(2027,1,3),'Plan de tareas'!$I$19>=DATE(2026,12,28)),1,0) -> 0
A19: C3 | B19: validacion/ — DTD/XSD 1.3, Schematron, integridad referencial (keys/keyref/conref) | C19: Full Stack Developer | D19: =IF(AND('Plan de tareas'!$H$20<=DATE(2026,9,13),'Plan de tareas'!$I$20>=DATE(2026,9,7)),1,0) -> 0 | E19: =IF(AND('Plan de tareas'!$H$20<=DATE(2026,9,20),'Plan de tareas'!$I$20>=DATE(2026,9,14)),1,0) -> 0 | F19: =IF(AND('Plan de tareas'!$H$20<=DATE(2026,9,27),'Plan de tareas'!$I$20>=DATE(2026,9,21)),1,0) -> 0 | G19: =IF(AND('Plan de tareas'!$H$20<=DATE(2026,10,4),'Plan de tareas'!$I$20>=DATE(2026,9,28)),1,0) -> 1 | H19: =IF(AND('Plan de tareas'!$H$20<=DATE(2026,10,11),'Plan de tareas'!$I$20>=DATE(2026,10,5)),1,0) -> 0 | I19: =IF(AND('Plan de tareas'!$H$20<=DATE(2026,10,18),'Plan de tareas'!$I$20>=DATE(2026,10,12)),1,0) -> 0 | J19: =IF(AND('Plan de tareas'!$H$20<=DATE(2026,10,25),'Plan de tareas'!$I$20>=DATE(2026,10,19)),1,0) -> 0 | K19: =IF(AND('Plan de tareas'!$H$20<=DATE(2026,11,1),'Plan de tareas'!$I$20>=DATE(2026,10,26)),1,0) -> 0 | L19: =IF(AND('Plan de tareas'!$H$20<=DATE(2026,11,8),'Plan de tareas'!$I$20>=DATE(2026,11,2)),1,0) -> 0 | M19: =IF(AND('Plan de tareas'!$H$20<=DATE(2026,11,15),'Plan de tareas'!$I$20>=DATE(2026,11,9)),1,0) -> 0 | N19: =IF(AND('Plan de tareas'!$H$20<=DATE(2026,11,22),'Plan de tareas'!$I$20>=DATE(2026,11,16)),1,0) -> 0 | O19: =IF(AND('Plan de tareas'!$H$20<=DATE(2026,11,29),'Plan de tareas'!$I$20>=DATE(2026,11,23)),1,0) -> 0 | P19: =IF(AND('Plan de tareas'!$H$20<=DATE(2026,12,6),'Plan de tareas'!$I$20>=DATE(2026,11,30)),1,0) -> 0 | Q19: =IF(AND('Plan de tareas'!$H$20<=DATE(2026,12,13),'Plan de tareas'!$I$20>=DATE(2026,12,7)),1,0) -> 0 | R19: =IF(AND('Plan de tareas'!$H$20<=DATE(2026,12,20),'Plan de tareas'!$I$20>=DATE(2026,12,14)),1,0) -> 0 | S19: =IF(AND('Plan de tareas'!$H$20<=DATE(2026,12,27),'Plan de tareas'!$I$20>=DATE(2026,12,21)),1,0) -> 0 | T19: =IF(AND('Plan de tareas'!$H$20<=DATE(2027,1,3),'Plan de tareas'!$I$20>=DATE(2026,12,28)),1,0) -> 0
A20: D1 | B20: proyectos_service.py + router (aplica decisión A) | C20: Full Stack Developer | D20: =IF(AND('Plan de tareas'!$H$21<=DATE(2026,9,13),'Plan de tareas'!$I$21>=DATE(2026,9,7)),1,0) -> 0 | E20: =IF(AND('Plan de tareas'!$H$21<=DATE(2026,9,20),'Plan de tareas'!$I$21>=DATE(2026,9,14)),1,0) -> 0 | F20: =IF(AND('Plan de tareas'!$H$21<=DATE(2026,9,27),'Plan de tareas'!$I$21>=DATE(2026,9,21)),1,0) -> 0 | G20: =IF(AND('Plan de tareas'!$H$21<=DATE(2026,10,4),'Plan de tareas'!$I$21>=DATE(2026,9,28)),1,0) -> 0 | H20: =IF(AND('Plan de tareas'!$H$21<=DATE(2026,10,11),'Plan de tareas'!$I$21>=DATE(2026,10,5)),1,0) -> 1 | I20: =IF(AND('Plan de tareas'!$H$21<=DATE(2026,10,18),'Plan de tareas'!$I$21>=DATE(2026,10,12)),1,0) -> 0 | J20: =IF(AND('Plan de tareas'!$H$21<=DATE(2026,10,25),'Plan de tareas'!$I$21>=DATE(2026,10,19)),1,0) -> 0 | K20: =IF(AND('Plan de tareas'!$H$21<=DATE(2026,11,1),'Plan de tareas'!$I$21>=DATE(2026,10,26)),1,0) -> 0 | L20: =IF(AND('Plan de tareas'!$H$21<=DATE(2026,11,8),'Plan de tareas'!$I$21>=DATE(2026,11,2)),1,0) -> 0 | M20: =IF(AND('Plan de tareas'!$H$21<=DATE(2026,11,15),'Plan de tareas'!$I$21>=DATE(2026,11,9)),1,0) -> 0 | N20: =IF(AND('Plan de tareas'!$H$21<=DATE(2026,11,22),'Plan de tareas'!$I$21>=DATE(2026,11,16)),1,0) -> 0 | O20: =IF(AND('Plan de tareas'!$H$21<=DATE(2026,11,29),'Plan de tareas'!$I$21>=DATE(2026,11,23)),1,0) -> 0 | P20: =IF(AND('Plan de tareas'!$H$21<=DATE(2026,12,6),'Plan de tareas'!$I$21>=DATE(2026,11,30)),1,0) -> 0 | Q20: =IF(AND('Plan de tareas'!$H$21<=DATE(2026,12,13),'Plan de tareas'!$I$21>=DATE(2026,12,7)),1,0) -> 0 | R20: =IF(AND('Plan de tareas'!$H$21<=DATE(2026,12,20),'Plan de tareas'!$I$21>=DATE(2026,12,14)),1,0) -> 0 | S20: =IF(AND('Plan de tareas'!$H$21<=DATE(2026,12,27),'Plan de tareas'!$I$21>=DATE(2026,12,21)),1,0) -> 0 | T20: =IF(AND('Plan de tareas'!$H$21<=DATE(2027,1,3),'Plan de tareas'!$I$21>=DATE(2026,12,28)),1,0) -> 0
A21: D2 | B21: contenido_service.py + bookmap_service.py + routers | C21: Full Stack Developer | D21: =IF(AND('Plan de tareas'!$H$22<=DATE(2026,9,13),'Plan de tareas'!$I$22>=DATE(2026,9,7)),1,0) -> 0 | E21: =IF(AND('Plan de tareas'!$H$22<=DATE(2026,9,20),'Plan de tareas'!$I$22>=DATE(2026,9,14)),1,0) -> 0 | F21: =IF(AND('Plan de tareas'!$H$22<=DATE(2026,9,27),'Plan de tareas'!$I$22>=DATE(2026,9,21)),1,0) -> 0 | G21: =IF(AND('Plan de tareas'!$H$22<=DATE(2026,10,4),'Plan de tareas'!$I$22>=DATE(2026,9,28)),1,0) -> 0 | H21: =IF(AND('Plan de tareas'!$H$22<=DATE(2026,10,11),'Plan de tareas'!$I$22>=DATE(2026,10,5)),1,0) -> 1 | I21: =IF(AND('Plan de tareas'!$H$22<=DATE(2026,10,18),'Plan de tareas'!$I$22>=DATE(2026,10,12)),1,0) -> 0 | J21: =IF(AND('Plan de tareas'!$H$22<=DATE(2026,10,25),'Plan de tareas'!$I$22>=DATE(2026,10,19)),1,0) -> 0 | K21: =IF(AND('Plan de tareas'!$H$22<=DATE(2026,11,1),'Plan de tareas'!$I$22>=DATE(2026,10,26)),1,0) -> 0 | L21: =IF(AND('Plan de tareas'!$H$22<=DATE(2026,11,8),'Plan de tareas'!$I$22>=DATE(2026,11,2)),1,0) -> 0 | M21: =IF(AND('Plan de tareas'!$H$22<=DATE(2026,11,15),'Plan de tareas'!$I$22>=DATE(2026,11,9)),1,0) -> 0 | N21: =IF(AND('Plan de tareas'!$H$22<=DATE(2026,11,22),'Plan de tareas'!$I$22>=DATE(2026,11,16)),1,0) -> 0 | O21: =IF(AND('Plan de tareas'!$H$22<=DATE(2026,11,29),'Plan de tareas'!$I$22>=DATE(2026,11,23)),1,0) -> 0 | P21: =IF(AND('Plan de tareas'!$H$22<=DATE(2026,12,6),'Plan de tareas'!$I$22>=DATE(2026,11,30)),1,0) -> 0 | Q21: =IF(AND('Plan de tareas'!$H$22<=DATE(2026,12,13),'Plan de tareas'!$I$22>=DATE(2026,12,7)),1,0) -> 0 | R21: =IF(AND('Plan de tareas'!$H$22<=DATE(2026,12,20),'Plan de tareas'!$I$22>=DATE(2026,12,14)),1,0) -> 0 | S21: =IF(AND('Plan de tareas'!$H$22<=DATE(2026,12,27),'Plan de tareas'!$I$22>=DATE(2026,12,21)),1,0) -> 0 | T21: =IF(AND('Plan de tareas'!$H$22<=DATE(2027,1,3),'Plan de tareas'!$I$22>=DATE(2026,12,28)),1,0) -> 0
A22: D3 | B22: checkout_service.py + router (lock, revisión, dispara validación) | C22: Full Stack Developer | D22: =IF(AND('Plan de tareas'!$H$23<=DATE(2026,9,13),'Plan de tareas'!$I$23>=DATE(2026,9,7)),1,0) -> 0 | E22: =IF(AND('Plan de tareas'!$H$23<=DATE(2026,9,20),'Plan de tareas'!$I$23>=DATE(2026,9,14)),1,0) -> 0 | F22: =IF(AND('Plan de tareas'!$H$23<=DATE(2026,9,27),'Plan de tareas'!$I$23>=DATE(2026,9,21)),1,0) -> 0 | G22: =IF(AND('Plan de tareas'!$H$23<=DATE(2026,10,4),'Plan de tareas'!$I$23>=DATE(2026,9,28)),1,0) -> 0 | H22: =IF(AND('Plan de tareas'!$H$23<=DATE(2026,10,11),'Plan de tareas'!$I$23>=DATE(2026,10,5)),1,0) -> 1 | I22: =IF(AND('Plan de tareas'!$H$23<=DATE(2026,10,18),'Plan de tareas'!$I$23>=DATE(2026,10,12)),1,0) -> 1 | J22: =IF(AND('Plan de tareas'!$H$23<=DATE(2026,10,25),'Plan de tareas'!$I$23>=DATE(2026,10,19)),1,0) -> 0 | K22: =IF(AND('Plan de tareas'!$H$23<=DATE(2026,11,1),'Plan de tareas'!$I$23>=DATE(2026,10,26)),1,0) -> 0 | L22: =IF(AND('Plan de tareas'!$H$23<=DATE(2026,11,8),'Plan de tareas'!$I$23>=DATE(2026,11,2)),1,0) -> 0 | M22: =IF(AND('Plan de tareas'!$H$23<=DATE(2026,11,15),'Plan de tareas'!$I$23>=DATE(2026,11,9)),1,0) -> 0 | N22: =IF(AND('Plan de tareas'!$H$23<=DATE(2026,11,22),'Plan de tareas'!$I$23>=DATE(2026,11,16)),1,0) -> 0 | O22: =IF(AND('Plan de tareas'!$H$23<=DATE(2026,11,29),'Plan de tareas'!$I$23>=DATE(2026,11,23)),1,0) -> 0 | P22: =IF(AND('Plan de tareas'!$H$23<=DATE(2026,12,6),'Plan de tareas'!$I$23>=DATE(2026,11,30)),1,0) -> 0 | Q22: =IF(AND('Plan de tareas'!$H$23<=DATE(2026,12,13),'Plan de tareas'!$I$23>=DATE(2026,12,7)),1,0) -> 0 | R22: =IF(AND('Plan de tareas'!$H$23<=DATE(2026,12,20),'Plan de tareas'!$I$23>=DATE(2026,12,14)),1,0) -> 0 | S22: =IF(AND('Plan de tareas'!$H$23<=DATE(2026,12,27),'Plan de tareas'!$I$23>=DATE(2026,12,21)),1,0) -> 0 | T22: =IF(AND('Plan de tareas'!$H$23<=DATE(2027,1,3),'Plan de tareas'!$I$23>=DATE(2026,12,28)),1,0) -> 0
A23: D4 | B23: versiones_service.py + router (baselines, diff) | C23: Full Stack Developer | D23: =IF(AND('Plan de tareas'!$H$24<=DATE(2026,9,13),'Plan de tareas'!$I$24>=DATE(2026,9,7)),1,0) -> 0 | E23: =IF(AND('Plan de tareas'!$H$24<=DATE(2026,9,20),'Plan de tareas'!$I$24>=DATE(2026,9,14)),1,0) -> 0 | F23: =IF(AND('Plan de tareas'!$H$24<=DATE(2026,9,27),'Plan de tareas'!$I$24>=DATE(2026,9,21)),1,0) -> 0 | G23: =IF(AND('Plan de tareas'!$H$24<=DATE(2026,10,4),'Plan de tareas'!$I$24>=DATE(2026,9,28)),1,0) -> 0 | H23: =IF(AND('Plan de tareas'!$H$24<=DATE(2026,10,11),'Plan de tareas'!$I$24>=DATE(2026,10,5)),1,0) -> 0 | I23: =IF(AND('Plan de tareas'!$H$24<=DATE(2026,10,18),'Plan de tareas'!$I$24>=DATE(2026,10,12)),1,0) -> 1 | J23: =IF(AND('Plan de tareas'!$H$24<=DATE(2026,10,25),'Plan de tareas'!$I$24>=DATE(2026,10,19)),1,0) -> 0 | K23: =IF(AND('Plan de tareas'!$H$24<=DATE(2026,11,1),'Plan de tareas'!$I$24>=DATE(2026,10,26)),1,0) -> 0 | L23: =IF(AND('Plan de tareas'!$H$24<=DATE(2026,11,8),'Plan de tareas'!$I$24>=DATE(2026,11,2)),1,0) -> 0 | M23: =IF(AND('Plan de tareas'!$H$24<=DATE(2026,11,15),'Plan de tareas'!$I$24>=DATE(2026,11,9)),1,0) -> 0 | N23: =IF(AND('Plan de tareas'!$H$24<=DATE(2026,11,22),'Plan de tareas'!$I$24>=DATE(2026,11,16)),1,0) -> 0 | O23: =IF(AND('Plan de tareas'!$H$24<=DATE(2026,11,29),'Plan de tareas'!$I$24>=DATE(2026,11,23)),1,0) -> 0 | P23: =IF(AND('Plan de tareas'!$H$24<=DATE(2026,12,6),'Plan de tareas'!$I$24>=DATE(2026,11,30)),1,0) -> 0 | Q23: =IF(AND('Plan de tareas'!$H$24<=DATE(2026,12,13),'Plan de tareas'!$I$24>=DATE(2026,12,7)),1,0) -> 0 | R23: =IF(AND('Plan de tareas'!$H$24<=DATE(2026,12,20),'Plan de tareas'!$I$24>=DATE(2026,12,14)),1,0) -> 0 | S23: =IF(AND('Plan de tareas'!$H$24<=DATE(2026,12,27),'Plan de tareas'!$I$24>=DATE(2026,12,21)),1,0) -> 0 | T23: =IF(AND('Plan de tareas'!$H$24<=DATE(2027,1,3),'Plan de tareas'!$I$24>=DATE(2026,12,28)),1,0) -> 0
A24: D5 | B24: tareas_service.py + workflow_service.py + routers (RBAC en transiciones) | C24: Full Stack Developer | D24: =IF(AND('Plan de tareas'!$H$25<=DATE(2026,9,13),'Plan de tareas'!$I$25>=DATE(2026,9,7)),1,0) -> 0 | E24: =IF(AND('Plan de tareas'!$H$25<=DATE(2026,9,20),'Plan de tareas'!$I$25>=DATE(2026,9,14)),1,0) -> 0 | F24: =IF(AND('Plan de tareas'!$H$25<=DATE(2026,9,27),'Plan de tareas'!$I$25>=DATE(2026,9,21)),1,0) -> 0 | G24: =IF(AND('Plan de tareas'!$H$25<=DATE(2026,10,4),'Plan de tareas'!$I$25>=DATE(2026,9,28)),1,0) -> 0 | H24: =IF(AND('Plan de tareas'!$H$25<=DATE(2026,10,11),'Plan de tareas'!$I$25>=DATE(2026,10,5)),1,0) -> 0 | I24: =IF(AND('Plan de tareas'!$H$25<=DATE(2026,10,18),'Plan de tareas'!$I$25>=DATE(2026,10,12)),1,0) -> 1 | J24: =IF(AND('Plan de tareas'!$H$25<=DATE(2026,10,25),'Plan de tareas'!$I$25>=DATE(2026,10,19)),1,0) -> 1 | K24: =IF(AND('Plan de tareas'!$H$25<=DATE(2026,11,1),'Plan de tareas'!$I$25>=DATE(2026,10,26)),1,0) -> 0 | L24: =IF(AND('Plan de tareas'!$H$25<=DATE(2026,11,8),'Plan de tareas'!$I$25>=DATE(2026,11,2)),1,0) -> 0 | M24: =IF(AND('Plan de tareas'!$H$25<=DATE(2026,11,15),'Plan de tareas'!$I$25>=DATE(2026,11,9)),1,0) -> 0 | N24: =IF(AND('Plan de tareas'!$H$25<=DATE(2026,11,22),'Plan de tareas'!$I$25>=DATE(2026,11,16)),1,0) -> 0 | O24: =IF(AND('Plan de tareas'!$H$25<=DATE(2026,11,29),'Plan de tareas'!$I$25>=DATE(2026,11,23)),1,0) -> 0 | P24: =IF(AND('Plan de tareas'!$H$25<=DATE(2026,12,6),'Plan de tareas'!$I$25>=DATE(2026,11,30)),1,0) -> 0 | Q24: =IF(AND('Plan de tareas'!$H$25<=DATE(2026,12,13),'Plan de tareas'!$I$25>=DATE(2026,12,7)),1,0) -> 0 | R24: =IF(AND('Plan de tareas'!$H$25<=DATE(2026,12,20),'Plan de tareas'!$I$25>=DATE(2026,12,14)),1,0) -> 0 | S24: =IF(AND('Plan de tareas'!$H$25<=DATE(2026,12,27),'Plan de tareas'!$I$25>=DATE(2026,12,21)),1,0) -> 0 | T24: =IF(AND('Plan de tareas'!$H$25<=DATE(2027,1,3),'Plan de tareas'!$I$25>=DATE(2026,12,28)),1,0) -> 0
A25: D6 | B25: servilog_service.py + router | C25: Full Stack Developer | D25: =IF(AND('Plan de tareas'!$H$26<=DATE(2026,9,13),'Plan de tareas'!$I$26>=DATE(2026,9,7)),1,0) -> 0 | E25: =IF(AND('Plan de tareas'!$H$26<=DATE(2026,9,20),'Plan de tareas'!$I$26>=DATE(2026,9,14)),1,0) -> 0 | F25: =IF(AND('Plan de tareas'!$H$26<=DATE(2026,9,27),'Plan de tareas'!$I$26>=DATE(2026,9,21)),1,0) -> 0 | G25: =IF(AND('Plan de tareas'!$H$26<=DATE(2026,10,4),'Plan de tareas'!$I$26>=DATE(2026,9,28)),1,0) -> 0 | H25: =IF(AND('Plan de tareas'!$H$26<=DATE(2026,10,11),'Plan de tareas'!$I$26>=DATE(2026,10,5)),1,0) -> 0 | I25: =IF(AND('Plan de tareas'!$H$26<=DATE(2026,10,18),'Plan de tareas'!$I$26>=DATE(2026,10,12)),1,0) -> 0 | J25: =IF(AND('Plan de tareas'!$H$26<=DATE(2026,10,25),'Plan de tareas'!$I$26>=DATE(2026,10,19)),1,0) -> 1 | K25: =IF(AND('Plan de tareas'!$H$26<=DATE(2026,11,1),'Plan de tareas'!$I$26>=DATE(2026,10,26)),1,0) -> 0 | L25: =IF(AND('Plan de tareas'!$H$26<=DATE(2026,11,8),'Plan de tareas'!$I$26>=DATE(2026,11,2)),1,0) -> 0 | M25: =IF(AND('Plan de tareas'!$H$26<=DATE(2026,11,15),'Plan de tareas'!$I$26>=DATE(2026,11,9)),1,0) -> 0 | N25: =IF(AND('Plan de tareas'!$H$26<=DATE(2026,11,22),'Plan de tareas'!$I$26>=DATE(2026,11,16)),1,0) -> 0 | O25: =IF(AND('Plan de tareas'!$H$26<=DATE(2026,11,29),'Plan de tareas'!$I$26>=DATE(2026,11,23)),1,0) -> 0 | P25: =IF(AND('Plan de tareas'!$H$26<=DATE(2026,12,6),'Plan de tareas'!$I$26>=DATE(2026,11,30)),1,0) -> 0 | Q25: =IF(AND('Plan de tareas'!$H$26<=DATE(2026,12,13),'Plan de tareas'!$I$26>=DATE(2026,12,7)),1,0) -> 0 | R25: =IF(AND('Plan de tareas'!$H$26<=DATE(2026,12,20),'Plan de tareas'!$I$26>=DATE(2026,12,14)),1,0) -> 0 | S25: =IF(AND('Plan de tareas'!$H$26<=DATE(2026,12,27),'Plan de tareas'!$I$26>=DATE(2026,12,21)),1,0) -> 0 | T25: =IF(AND('Plan de tareas'!$H$26<=DATE(2027,1,3),'Plan de tareas'!$I$26>=DATE(2026,12,28)),1,0) -> 0
A26: D7 | B26: indice_extraccion_service.py + router | C26: Full Stack Developer | D26: =IF(AND('Plan de tareas'!$H$27<=DATE(2026,9,13),'Plan de tareas'!$I$27>=DATE(2026,9,7)),1,0) -> 0 | E26: =IF(AND('Plan de tareas'!$H$27<=DATE(2026,9,20),'Plan de tareas'!$I$27>=DATE(2026,9,14)),1,0) -> 0 | F26: =IF(AND('Plan de tareas'!$H$27<=DATE(2026,9,27),'Plan de tareas'!$I$27>=DATE(2026,9,21)),1,0) -> 0 | G26: =IF(AND('Plan de tareas'!$H$27<=DATE(2026,10,4),'Plan de tareas'!$I$27>=DATE(2026,9,28)),1,0) -> 0 | H26: =IF(AND('Plan de tareas'!$H$27<=DATE(2026,10,11),'Plan de tareas'!$I$27>=DATE(2026,10,5)),1,0) -> 0 | I26: =IF(AND('Plan de tareas'!$H$27<=DATE(2026,10,18),'Plan de tareas'!$I$27>=DATE(2026,10,12)),1,0) -> 0 | J26: =IF(AND('Plan de tareas'!$H$27<=DATE(2026,10,25),'Plan de tareas'!$I$27>=DATE(2026,10,19)),1,0) -> 1 | K26: =IF(AND('Plan de tareas'!$H$27<=DATE(2026,11,1),'Plan de tareas'!$I$27>=DATE(2026,10,26)),1,0) -> 0 | L26: =IF(AND('Plan de tareas'!$H$27<=DATE(2026,11,8),'Plan de tareas'!$I$27>=DATE(2026,11,2)),1,0) -> 0 | M26: =IF(AND('Plan de tareas'!$H$27<=DATE(2026,11,15),'Plan de tareas'!$I$27>=DATE(2026,11,9)),1,0) -> 0 | N26: =IF(AND('Plan de tareas'!$H$27<=DATE(2026,11,22),'Plan de tareas'!$I$27>=DATE(2026,11,16)),1,0) -> 0 | O26: =IF(AND('Plan de tareas'!$H$27<=DATE(2026,11,29),'Plan de tareas'!$I$27>=DATE(2026,11,23)),1,0) -> 0 | P26: =IF(AND('Plan de tareas'!$H$27<=DATE(2026,12,6),'Plan de tareas'!$I$27>=DATE(2026,11,30)),1,0) -> 0 | Q26: =IF(AND('Plan de tareas'!$H$27<=DATE(2026,12,13),'Plan de tareas'!$I$27>=DATE(2026,12,7)),1,0) -> 0 | R26: =IF(AND('Plan de tareas'!$H$27<=DATE(2026,12,20),'Plan de tareas'!$I$27>=DATE(2026,12,14)),1,0) -> 0 | S26: =IF(AND('Plan de tareas'!$H$27<=DATE(2026,12,27),'Plan de tareas'!$I$27>=DATE(2026,12,21)),1,0) -> 0 | T26: =IF(AND('Plan de tareas'!$H$27<=DATE(2027,1,3),'Plan de tareas'!$I$27>=DATE(2026,12,28)),1,0) -> 0
A27: D8 | B27: busqueda_service.py + conexión real a OpenSearch | C27: Full Stack Developer | D27: =IF(AND('Plan de tareas'!$H$28<=DATE(2026,9,13),'Plan de tareas'!$I$28>=DATE(2026,9,7)),1,0) -> 0 | E27: =IF(AND('Plan de tareas'!$H$28<=DATE(2026,9,20),'Plan de tareas'!$I$28>=DATE(2026,9,14)),1,0) -> 0 | F27: =IF(AND('Plan de tareas'!$H$28<=DATE(2026,9,27),'Plan de tareas'!$I$28>=DATE(2026,9,21)),1,0) -> 0 | G27: =IF(AND('Plan de tareas'!$H$28<=DATE(2026,10,4),'Plan de tareas'!$I$28>=DATE(2026,9,28)),1,0) -> 0 | H27: =IF(AND('Plan de tareas'!$H$28<=DATE(2026,10,11),'Plan de tareas'!$I$28>=DATE(2026,10,5)),1,0) -> 0 | I27: =IF(AND('Plan de tareas'!$H$28<=DATE(2026,10,18),'Plan de tareas'!$I$28>=DATE(2026,10,12)),1,0) -> 0 | J27: =IF(AND('Plan de tareas'!$H$28<=DATE(2026,10,25),'Plan de tareas'!$I$28>=DATE(2026,10,19)),1,0) -> 0 | K27: =IF(AND('Plan de tareas'!$H$28<=DATE(2026,11,1),'Plan de tareas'!$I$28>=DATE(2026,10,26)),1,0) -> 1 | L27: =IF(AND('Plan de tareas'!$H$28<=DATE(2026,11,8),'Plan de tareas'!$I$28>=DATE(2026,11,2)),1,0) -> 0 | M27: =IF(AND('Plan de tareas'!$H$28<=DATE(2026,11,15),'Plan de tareas'!$I$28>=DATE(2026,11,9)),1,0) -> 0 | N27: =IF(AND('Plan de tareas'!$H$28<=DATE(2026,11,22),'Plan de tareas'!$I$28>=DATE(2026,11,16)),1,0) -> 0 | O27: =IF(AND('Plan de tareas'!$H$28<=DATE(2026,11,29),'Plan de tareas'!$I$28>=DATE(2026,11,23)),1,0) -> 0 | P27: =IF(AND('Plan de tareas'!$H$28<=DATE(2026,12,6),'Plan de tareas'!$I$28>=DATE(2026,11,30)),1,0) -> 0 | Q27: =IF(AND('Plan de tareas'!$H$28<=DATE(2026,12,13),'Plan de tareas'!$I$28>=DATE(2026,12,7)),1,0) -> 0 | R27: =IF(AND('Plan de tareas'!$H$28<=DATE(2026,12,20),'Plan de tareas'!$I$28>=DATE(2026,12,14)),1,0) -> 0 | S27: =IF(AND('Plan de tareas'!$H$28<=DATE(2026,12,27),'Plan de tareas'!$I$28>=DATE(2026,12,21)),1,0) -> 0 | T27: =IF(AND('Plan de tareas'!$H$28<=DATE(2027,1,3),'Plan de tareas'!$I$28>=DATE(2026,12,28)),1,0) -> 0
A28: D9 | B28: reports_service.py + router | C28: Full Stack Developer | D28: =IF(AND('Plan de tareas'!$H$29<=DATE(2026,9,13),'Plan de tareas'!$I$29>=DATE(2026,9,7)),1,0) -> 0 | E28: =IF(AND('Plan de tareas'!$H$29<=DATE(2026,9,20),'Plan de tareas'!$I$29>=DATE(2026,9,14)),1,0) -> 0 | F28: =IF(AND('Plan de tareas'!$H$29<=DATE(2026,9,27),'Plan de tareas'!$I$29>=DATE(2026,9,21)),1,0) -> 0 | G28: =IF(AND('Plan de tareas'!$H$29<=DATE(2026,10,4),'Plan de tareas'!$I$29>=DATE(2026,9,28)),1,0) -> 0 | H28: =IF(AND('Plan de tareas'!$H$29<=DATE(2026,10,11),'Plan de tareas'!$I$29>=DATE(2026,10,5)),1,0) -> 0 | I28: =IF(AND('Plan de tareas'!$H$29<=DATE(2026,10,18),'Plan de tareas'!$I$29>=DATE(2026,10,12)),1,0) -> 0 | J28: =IF(AND('Plan de tareas'!$H$29<=DATE(2026,10,25),'Plan de tareas'!$I$29>=DATE(2026,10,19)),1,0) -> 0 | K28: =IF(AND('Plan de tareas'!$H$29<=DATE(2026,11,1),'Plan de tareas'!$I$29>=DATE(2026,10,26)),1,0) -> 1 | L28: =IF(AND('Plan de tareas'!$H$29<=DATE(2026,11,8),'Plan de tareas'!$I$29>=DATE(2026,11,2)),1,0) -> 0 | M28: =IF(AND('Plan de tareas'!$H$29<=DATE(2026,11,15),'Plan de tareas'!$I$29>=DATE(2026,11,9)),1,0) -> 0 | N28: =IF(AND('Plan de tareas'!$H$29<=DATE(2026,11,22),'Plan de tareas'!$I$29>=DATE(2026,11,16)),1,0) -> 0 | O28: =IF(AND('Plan de tareas'!$H$29<=DATE(2026,11,29),'Plan de tareas'!$I$29>=DATE(2026,11,23)),1,0) -> 0 | P28: =IF(AND('Plan de tareas'!$H$29<=DATE(2026,12,6),'Plan de tareas'!$I$29>=DATE(2026,11,30)),1,0) -> 0 | Q28: =IF(AND('Plan de tareas'!$H$29<=DATE(2026,12,13),'Plan de tareas'!$I$29>=DATE(2026,12,7)),1,0) -> 0 | R28: =IF(AND('Plan de tareas'!$H$29<=DATE(2026,12,20),'Plan de tareas'!$I$29>=DATE(2026,12,14)),1,0) -> 0 | S28: =IF(AND('Plan de tareas'!$H$29<=DATE(2026,12,27),'Plan de tareas'!$I$29>=DATE(2026,12,21)),1,0) -> 0 | T28: =IF(AND('Plan de tareas'!$H$29<=DATE(2027,1,3),'Plan de tareas'!$I$29>=DATE(2026,12,28)),1,0) -> 0
A29: D10 | B29: rbac_service.py + admin_service.py + auditoria_service.py + comentarios_service.py + routers | C29: Full Stack Developer | D29: =IF(AND('Plan de tareas'!$H$30<=DATE(2026,9,13),'Plan de tareas'!$I$30>=DATE(2026,9,7)),1,0) -> 0 | E29: =IF(AND('Plan de tareas'!$H$30<=DATE(2026,9,20),'Plan de tareas'!$I$30>=DATE(2026,9,14)),1,0) -> 0 | F29: =IF(AND('Plan de tareas'!$H$30<=DATE(2026,9,27),'Plan de tareas'!$I$30>=DATE(2026,9,21)),1,0) -> 0 | G29: =IF(AND('Plan de tareas'!$H$30<=DATE(2026,10,4),'Plan de tareas'!$I$30>=DATE(2026,9,28)),1,0) -> 0 | H29: =IF(AND('Plan de tareas'!$H$30<=DATE(2026,10,11),'Plan de tareas'!$I$30>=DATE(2026,10,5)),1,0) -> 0 | I29: =IF(AND('Plan de tareas'!$H$30<=DATE(2026,10,18),'Plan de tareas'!$I$30>=DATE(2026,10,12)),1,0) -> 0 | J29: =IF(AND('Plan de tareas'!$H$30<=DATE(2026,10,25),'Plan de tareas'!$I$30>=DATE(2026,10,19)),1,0) -> 0 | K29: =IF(AND('Plan de tareas'!$H$30<=DATE(2026,11,1),'Plan de tareas'!$I$30>=DATE(2026,10,26)),1,0) -> 1 | L29: =IF(AND('Plan de tareas'!$H$30<=DATE(2026,11,8),'Plan de tareas'!$I$30>=DATE(2026,11,2)),1,0) -> 1 | M29: =IF(AND('Plan de tareas'!$H$30<=DATE(2026,11,15),'Plan de tareas'!$I$30>=DATE(2026,11,9)),1,0) -> 0 | N29: =IF(AND('Plan de tareas'!$H$30<=DATE(2026,11,22),'Plan de tareas'!$I$30>=DATE(2026,11,16)),1,0) -> 0 | O29: =IF(AND('Plan de tareas'!$H$30<=DATE(2026,11,29),'Plan de tareas'!$I$30>=DATE(2026,11,23)),1,0) -> 0 | P29: =IF(AND('Plan de tareas'!$H$30<=DATE(2026,12,6),'Plan de tareas'!$I$30>=DATE(2026,11,30)),1,0) -> 0 | Q29: =IF(AND('Plan de tareas'!$H$30<=DATE(2026,12,13),'Plan de tareas'!$I$30>=DATE(2026,12,7)),1,0) -> 0 | R29: =IF(AND('Plan de tareas'!$H$30<=DATE(2026,12,20),'Plan de tareas'!$I$30>=DATE(2026,12,14)),1,0) -> 0 | S29: =IF(AND('Plan de tareas'!$H$30<=DATE(2026,12,27),'Plan de tareas'!$I$30>=DATE(2026,12,21)),1,0) -> 0 | T29: =IF(AND('Plan de tareas'!$H$30<=DATE(2027,1,3),'Plan de tareas'!$I$30>=DATE(2026,12,28)),1,0) -> 0
A30: D11 | B30: publisher_service.py + router | C30: Full Stack Developer | D30: =IF(AND('Plan de tareas'!$H$31<=DATE(2026,9,13),'Plan de tareas'!$I$31>=DATE(2026,9,7)),1,0) -> 0 | E30: =IF(AND('Plan de tareas'!$H$31<=DATE(2026,9,20),'Plan de tareas'!$I$31>=DATE(2026,9,14)),1,0) -> 0 | F30: =IF(AND('Plan de tareas'!$H$31<=DATE(2026,9,27),'Plan de tareas'!$I$31>=DATE(2026,9,21)),1,0) -> 0 | G30: =IF(AND('Plan de tareas'!$H$31<=DATE(2026,10,4),'Plan de tareas'!$I$31>=DATE(2026,9,28)),1,0) -> 0 | H30: =IF(AND('Plan de tareas'!$H$31<=DATE(2026,10,11),'Plan de tareas'!$I$31>=DATE(2026,10,5)),1,0) -> 0 | I30: =IF(AND('Plan de tareas'!$H$31<=DATE(2026,10,18),'Plan de tareas'!$I$31>=DATE(2026,10,12)),1,0) -> 0 | J30: =IF(AND('Plan de tareas'!$H$31<=DATE(2026,10,25),'Plan de tareas'!$I$31>=DATE(2026,10,19)),1,0) -> 0 | K30: =IF(AND('Plan de tareas'!$H$31<=DATE(2026,11,1),'Plan de tareas'!$I$31>=DATE(2026,10,26)),1,0) -> 0 | L30: =IF(AND('Plan de tareas'!$H$31<=DATE(2026,11,8),'Plan de tareas'!$I$31>=DATE(2026,11,2)),1,0) -> 1 | M30: =IF(AND('Plan de tareas'!$H$31<=DATE(2026,11,15),'Plan de tareas'!$I$31>=DATE(2026,11,9)),1,0) -> 0 | N30: =IF(AND('Plan de tareas'!$H$31<=DATE(2026,11,22),'Plan de tareas'!$I$31>=DATE(2026,11,16)),1,0) -> 0 | O30: =IF(AND('Plan de tareas'!$H$31<=DATE(2026,11,29),'Plan de tareas'!$I$31>=DATE(2026,11,23)),1,0) -> 0 | P30: =IF(AND('Plan de tareas'!$H$31<=DATE(2026,12,6),'Plan de tareas'!$I$31>=DATE(2026,11,30)),1,0) -> 0 | Q30: =IF(AND('Plan de tareas'!$H$31<=DATE(2026,12,13),'Plan de tareas'!$I$31>=DATE(2026,12,7)),1,0) -> 0 | R30: =IF(AND('Plan de tareas'!$H$31<=DATE(2026,12,20),'Plan de tareas'!$I$31>=DATE(2026,12,14)),1,0) -> 0 | S30: =IF(AND('Plan de tareas'!$H$31<=DATE(2026,12,27),'Plan de tareas'!$I$31>=DATE(2026,12,21)),1,0) -> 0 | T30: =IF(AND('Plan de tareas'!$H$31<=DATE(2027,1,3),'Plan de tareas'!$I$31>=DATE(2026,12,28)),1,0) -> 0
A31: D12 | B31: worker/ — cola async + DITA-OT/Saxon + integración con el pipeline confirmado en T-A4 | C31: Full Stack Developer | D31: =IF(AND('Plan de tareas'!$H$32<=DATE(2026,9,13),'Plan de tareas'!$I$32>=DATE(2026,9,7)),1,0) -> 0 | E31: =IF(AND('Plan de tareas'!$H$32<=DATE(2026,9,20),'Plan de tareas'!$I$32>=DATE(2026,9,14)),1,0) -> 0 | F31: =IF(AND('Plan de tareas'!$H$32<=DATE(2026,9,27),'Plan de tareas'!$I$32>=DATE(2026,9,21)),1,0) -> 0 | G31: =IF(AND('Plan de tareas'!$H$32<=DATE(2026,10,4),'Plan de tareas'!$I$32>=DATE(2026,9,28)),1,0) -> 0 | H31: =IF(AND('Plan de tareas'!$H$32<=DATE(2026,10,11),'Plan de tareas'!$I$32>=DATE(2026,10,5)),1,0) -> 0 | I31: =IF(AND('Plan de tareas'!$H$32<=DATE(2026,10,18),'Plan de tareas'!$I$32>=DATE(2026,10,12)),1,0) -> 0 | J31: =IF(AND('Plan de tareas'!$H$32<=DATE(2026,10,25),'Plan de tareas'!$I$32>=DATE(2026,10,19)),1,0) -> 0 | K31: =IF(AND('Plan de tareas'!$H$32<=DATE(2026,11,1),'Plan de tareas'!$I$32>=DATE(2026,10,26)),1,0) -> 0 | L31: =IF(AND('Plan de tareas'!$H$32<=DATE(2026,11,8),'Plan de tareas'!$I$32>=DATE(2026,11,2)),1,0) -> 1 | M31: =IF(AND('Plan de tareas'!$H$32<=DATE(2026,11,15),'Plan de tareas'!$I$32>=DATE(2026,11,9)),1,0) -> 1 | N31: =IF(AND('Plan de tareas'!$H$32<=DATE(2026,11,22),'Plan de tareas'!$I$32>=DATE(2026,11,16)),1,0) -> 0 | O31: =IF(AND('Plan de tareas'!$H$32<=DATE(2026,11,29),'Plan de tareas'!$I$32>=DATE(2026,11,23)),1,0) -> 0 | P31: =IF(AND('Plan de tareas'!$H$32<=DATE(2026,12,6),'Plan de tareas'!$I$32>=DATE(2026,11,30)),1,0) -> 0 | Q31: =IF(AND('Plan de tareas'!$H$32<=DATE(2026,12,13),'Plan de tareas'!$I$32>=DATE(2026,12,7)),1,0) -> 0 | R31: =IF(AND('Plan de tareas'!$H$32<=DATE(2026,12,20),'Plan de tareas'!$I$32>=DATE(2026,12,14)),1,0) -> 0 | S31: =IF(AND('Plan de tareas'!$H$32<=DATE(2026,12,27),'Plan de tareas'!$I$32>=DATE(2026,12,21)),1,0) -> 0 | T31: =IF(AND('Plan de tareas'!$H$32<=DATE(2027,1,3),'Plan de tareas'!$I$32>=DATE(2026,12,28)),1,0) -> 0
